<?xml version="1.0" ?>
<robot name="irb_120" xmlns:xacro="http://ros.org/wiki/xacro">
  <link name="base_link">
	</link>
	<link name="link_1">
	</link>
	<link name="link_2">
	</link>
	<link name="link_3">
	</link>
	<link name="link_4">
	</link>
	<link name="link_5">
	</link>
	<link name="link_6">
	</link>
	
	<joint name="joint1" type="revolute">
		<parent link="base_link"/>
		<child link="link_1"/>
		<limit effort="300" lower="-2.88" upper="2.88" velocity="4.36"/>
		<axis xyz="0 0 1"/>
		<origin rpy="0 0 0" xyz="0 0 0"/>
	</joint>
	<joint name="joint2" type="revolute">
		<parent link="link_1"/>
		<child link="link_2"/>
		<limit effort="300" lower="-1.92" upper="1.92" velocity="4.36"/>
		<axis xyz="0 0 1"/>
    <origin rpy="1.571 0 0" xyz="0 0 0.290"/>
	</joint>
	<joint name="joint3" type="revolute">
		<parent link="link_2"/>
		<child link="link_3"/>
		<limit effort="300" lower="-1.575" upper="1.23" velocity="4.36"/>
		<axis xyz="0 0 1"/>
		<origin rpy="0 0 0" xyz="0 0.270 0"/>
	</joint>
	<joint name="joint4" type="revolute">
		<parent link="link_3"/>
		<child link="link_4"/>
		<limit effort="300" lower="-2.80" upper="2.80" velocity="5.58"/>
		<axis xyz="0 0 1"/>
		<origin rpy="0 1.571 0" xyz="0 0.070 0"/>
	</joint>
	<joint name="joint5" type="revolute">
		<parent link="link_4"/>
		<child link="link_5"/>
		<limit effort="300" lower="-2.10" upper="2.10" velocity="5.58"/>
		<axis xyz="0 0 1"/>
		<origin rpy="0 -1.571 0" xyz="0 0 0.302"/>
	</joint>
	<joint name="joint6" type="revolute">
		<parent link="link_5"/>
		<child link="link_6"/>
		<limit effort="300" lower="-6.985" upper="6.985" velocity="7.33"/>
		<axis xyz="0 0 1"/>
		<origin rpy="0 1.571 0" xyz="0.072 0 0"/>
	</joint>
</robot>
